			Exception
*************************************************************

Qu'est-ce qu'une exception ? :
------------------------------

D√©finition : 
------------

Une exception est un m√©canisme qui interrompt l‚Äôex√©cution normale 
du programme lorsqu‚Äôune condition d‚Äôerreur survient, pour transf√©rer le contr√¥le √† 
un gestionnaire d‚Äôerreur appropri√© (un bloc catch).

R√¥le :
------

Les exceptions servent √† g√©rer les erreurs d‚Äôex√©cution de mani√®re structur√©e.
Elles permettent de s√©parer le code de traitement des erreurs du code principal, 
ce qui simplifie le programme en √©vitant de v√©rifier constamment les codes de retour.

Propagation :
-------------

Si une exception n‚Äôest pas captur√©e dans la fonction o√π elle survient, elle est propag√©e 
√† la fonction appelante. Ce processus se r√©p√®te de proche en proche jusqu‚Äô√† ce qu‚Äôun bloc 
catch la traite ou, √† d√©faut, jusqu‚Äô√† la fin du programme .
(appel de std::terminate si aucune capture n‚Äôa lieu).

Syntaxe de base (try, throw, catch) :
-------------------------------------

    try { ... } : d√©finit un bloc de code prot√©g√© o√π des exceptions peuvent se produire. 
On y place le code "√† risque".

    throw expr; : lance (l√©ve) une exception ‚Äì typiquement appel√© √† l‚Äôint√©rieur d‚Äôun try 
lorsqu‚Äôune erreur est d√©tect√©e ‚Äì en encapsulant une information sur l‚Äôerreur dans expr 
(par exemple un objet d‚Äôexception).

    catch (TypeExc & e) { ... } : intercepte et traite une exception de type TypeExc 
lanc√©e dans le bloc try associ√©. Le param√®tre e permet d‚Äôacc√©der √† l‚Äôobjet exception 
(il est d‚Äôusage de le passer par r√©f√©rence constante).

üëâ Il peut y avoir plusieurs blocs catch √† la suite d‚Äôun m√™me try pour g√©rer diff√©rents types 
d‚Äôexceptions. Placez les catch du plus sp√©cifique au plus g√©n√©ral. 

Un catch (...) (trois points) en dernier peut servir de filet global capturant toute exception,
quelque soit son type.

Exemple :
---------

L‚Äôexemple suivant illustre le lancement et la capture d‚Äôune exception en C++. 
La fonction division lance une exception si on tente de diviser par z√©ro, 
et le bloc try/catch dans main capture cette erreur pour l‚Äôafficher 
sans interrompre brutalement le programme :

#include <iostream>
#include <stdexcept>
using namespace std;

int division(int a, int b) 
{
    if (b == 0) {
        throw runtime_error("Division par z\u00e9ro !");
    }
    return a / b;
}

int main() 
{
    try 
{
        cout << "R√©sultat : " << division(10, 2) << endl;  // Pas d'erreur
        cout << "R√©sultat : " << division(10, 0) << endl;  // Provoque une exception
} 
catch (const runtime_error &e) 
{
        cerr << "Erreur : " << e.what() << endl;     // Affiche "Erreur : Division par z\u00e9ro !"
}

    cout << "Fin du programme." << endl;                   // Le programme continue
}

************************************************************************************
