			Exception
*************************************************************

Qu'est-ce qu'une exception ? :
------------------------------

D√©finition : 
------------

Une exception est un m√©canisme qui interrompt l‚Äôex√©cution normale 
du programme lorsqu‚Äôune condition d‚Äôerreur survient, pour transf√©rer le contr√¥le √† 
un gestionnaire d‚Äôerreur appropri√© (un bloc catch).

R√¥le :
------

Les exceptions servent √† g√©rer les erreurs d‚Äôex√©cution de mani√®re structur√©e.
Elles permettent de s√©parer le code de traitement des erreurs du code principal, 
ce qui simplifie le programme en √©vitant de v√©rifier constamment les codes de retour.

Propagation :
-------------

Si une exception n‚Äôest pas captur√©e dans la fonction o√π elle survient, elle est propag√©e 
√† la fonction appelante. Ce processus se r√©p√®te de proche en proche jusqu‚Äô√† ce qu‚Äôun bloc 
catch la traite ou, √† d√©faut, jusqu‚Äô√† la fin du programme .
(appel de std::terminate si aucune capture n‚Äôa lieu).

Syntaxe de base (try, throw, catch) :
-------------------------------------

    try { ... } : d√©finit un bloc de code prot√©g√© o√π des exceptions peuvent se produire. 
On y place le code "√† risque".

    throw expr; : lance (l√©ve) une exception ‚Äì typiquement appel√© √† l‚Äôint√©rieur d‚Äôun try 
lorsqu‚Äôune erreur est d√©tect√©e ‚Äì en encapsulant une information sur l‚Äôerreur dans expr 
(par exemple un objet d‚Äôexception).

    catch (TypeExc & e) { ... } : intercepte et traite une exception de type TypeExc 
lanc√©e dans le bloc try associ√©. Le param√®tre e permet d‚Äôacc√©der √† l‚Äôobjet exception 
(il est d‚Äôusage de le passer par r√©f√©rence constante).

üëâ Il peut y avoir plusieurs blocs catch √† la suite d‚Äôun m√™me try pour g√©rer diff√©rents types 
d‚Äôexceptions. Placez les catch du plus sp√©cifique au plus g√©n√©ral. 

Un catch (...) (trois points) en dernier peut servir de filet global capturant toute exception,
quelque soit son type.

Exemple :
---------

L‚Äôexemple suivant illustre le lancement et la capture d‚Äôune exception en C++. 
La fonction division lance une exception si on tente de diviser par z√©ro, 
et le bloc try/catch dans main capture cette erreur pour l‚Äôafficher 
sans interrompre brutalement le programme :

#include <iostream>
#include <stdexcept>
using namespace std;

int division(int a, int b) 
{
    if (b == 0) {
        throw runtime_error("Division par z\u00e9ro !");
    }
    return a / b;
}

int main() 
{
    try 
{
        cout << "R√©sultat : " << division(10, 2) << endl;  // Pas d'erreur
        cout << "R√©sultat : " << division(10, 0) << endl;  // Provoque une exception
} 
catch (const runtime_error &e) 
{
        cerr << "Erreur : " << e.what() << endl;     // Affiche "Erreur : Division par z\u00e9ro !"
}

    cout << "Fin du programme." << endl;                   // Le programme continue
}

La m√©thode what() :
-------------------

what() est une m√©thode membre de la classe std::exception et de toutes les classes qui en h√©ritent 
(comme std::runtime_error, std::invalid_argument, etc.).

Elle sert √† r√©cup√©rer un message d‚Äôerreur sous forme de cha√Æne de caract√®res (C-string).

üìå D√©finition :
---------------

virtual const char* what() const throw();

+--------------+---------------------------------------------------------------+
| √âl√©ment      | Signification                                                 |
+--------------+---------------------------------------------------------------+
| virtual      | Permet la red√©finition dans les classes filles.               |
| const        | Ne modifie pas l'objet.                                       |
| throw()      | Garantie que la fonction ne lance pas d'exception.            |
| const char*  | Retourne un C-string (cha√Æne de caract√®res).                  |
+--------------+---------------------------------------------------------------+

Exemple simple :
----------------

#include <iostream>
#include <exception>

int main()
{
    try
    {
        throw std::runtime_error("Erreur critique !");
    }
    catch (const std::exception &e)
    {
        std::cerr << "Exception : " << e.what() << std::endl;
    }
}


R√©sultat :

Exception : Erreur critique !

üöÄ Quand l‚Äôutiliser ?

Tu utilises what() quand tu veux : 

‚úÖ Afficher un message d'erreur propre
‚úÖ Conna√Ætre la cause de l'exception
‚úÖ Logger des erreurs ou les transmettre

Exemple avec exception personnalis√©e :
--------------------------------------

#include <exception>

class MyException : public std::exception
{
public:
    const char* what() const noexcept override
    {
        return "Ceci est une exception personnalis√©e.";
    }
};

Attention :
-----------

what() retourne un const char*, donc :

    Il vaut mieux l‚Äôutiliser imm√©diatement (std::cerr << e.what();)

    Il ne faut pas essayer de modifier le r√©sultat

Pour r√©sumer simplement :
-------------------------

Si c‚Äôest une exception native du C++ (std::exception, std::runtime_error, std::invalid_argument, etc.) ‚Üí
---------------------------------------------------------------------------------------------------------

La m√©thode what() retourne un message que tu as pass√© lors du throw :

throw std::runtime_error("Erreur critique");

‚Üí what() renverra "Erreur critique"

Si c‚Äôest une exception personnalis√©e (comme GradeTooHighException) ‚Üí
---------------------------------------------------------------------

La m√©thode what() retourne la cha√Æne que tu as d√©finie toi-m√™me dans la red√©finition de la fonction :

const char* GradeTooHighException::what() const throw()
{
    return "Grade trop √©lev√© !";
}

‚Üí what() renverra "Grade trop √©lev√© !"

üî• Donc, en clair :

    La seule mission de what() ‚Üí fournir une explication textuelle sur l'erreur.
    Rien de plus.
    C‚Äôest juste un moyen d‚Äôobtenir un message que tu peux afficher ou logguer.

************************************************************************************
