				Gestion des exceptions en C++ â€” try / catch
************************************************************************************************************************************

ðŸš€ Quâ€™est-ce quâ€™une exception ? :
---------------------------------

Une exception est un mÃ©canisme qui permet de gÃ©rer les erreurs ou les situations anormales pendant lâ€™exÃ©cution du programme.

Quand un problÃ¨me survient, on peut lancer (throw) une exception.
Si elle n'est pas attrapÃ©e (catch), le programme se termine brutalement.

ðŸŸ¢ Syntaxe gÃ©nÃ©rale :
---------------------

try
{
    // Code qui pourrait gÃ©nÃ©rer une exception
}
catch (const TypeException &e)
{
    // Code pour gÃ©rer l'exception
}

ðŸ”¥ Exemple simple :
-------------------

#include <iostream>
#include <exception>

int main()
{
    try
    {
        throw std::runtime_error("Une erreur est survenue !");
    }
    catch (const std::exception &e)
    {
        std::cerr << "Erreur attrapÃ©e : " << e.what() << std::endl;
    }

    std::cout << "Le programme continue." << std::endl;
    return 0;
}

RÃ©sultat :
----------

Erreur attrapÃ©e : Une erreur est survenue !

Le programme continue.

Pourquoi utiliser try / catch ? :
---------------------------------

âœ… Pour empÃªcher que le programme plante brutalement en cas d'erreur
âœ… Pour rÃ©cupÃ©rer et traiter l'information sur l'erreur
âœ… Pour protÃ©ger les zones critiques du programme

Le mÃ©canisme complet :
----------------------

    throw â†’ Permet de lancer une exception

    try â†’ Permet de protÃ©ger un bloc de code

    catch â†’ Permet de attraper l'exception et d'agir


ðŸ§© Plusieurs catch :
--------------------

On peut attraper plusieurs types dâ€™exceptions :

try
{
    // Code qui peut gÃ©nÃ©rer plusieurs types d'exceptions
}
catch (const std::invalid_argument &e)
{
    std::cerr << "Argument invalide : " << e.what() << std::endl;
}
catch (const std::out_of_range &e)
{
    std::cerr << "Hors limites : " << e.what() << std::endl;
}
catch (const std::exception &e)
{
    std::cerr << "Autre erreur : " << e.what() << std::endl;
}


Attraper toutes les exceptions :
--------------------------------

Il existe un catch spÃ©cial qui attrape n'importe quelle exception (mÃªme sans info) :

try
{
    // Code
}
catch (...)
{
    std::cerr << "Une exception inconnue a Ã©tÃ© attrapÃ©e." << std::endl;
}

CrÃ©er sa propre exception :
---------------------------

Tu peux aussi crÃ©er ta propre classe d'exception en hÃ©ritant de std::exception :

#include <exception>

class MyException : public std::exception
{
public:
    const char* what() const noexcept override
    {
        return "Ceci est une exception personnalisÃ©e.";
    }
};

Puis l'utiliser :

try
{
    throw MyException();
}
catch (const MyException &e)
{
    std::cerr << e.what() << std::endl;
}

Les arguments de catch :
------------------------

Quand on Ã©crit un bloc catch, on doit indiquer le type dâ€™exception quâ€™on veut attraper.
Cet argument dÃ©termine ce quâ€™on attrape et comment on y accÃ¨de.

ðŸ“Œ Structure d'un argument de catch :
-------------------------------------

catch (const TypeException &e)

DÃ©composition :
---------------

+----------------+-------------------------------------------------------------------------------------------+
| Ã‰lÃ©ment       | Signification                                                                              |
+---------------+--------------------------------------------------------------------------------------------+
| TypeException | Le type de l'exception que l'on souhaite attraper (ex : std::exception, std::runtime_error)|
| const         | L'exception est passÃ©e en constante â†’ on ne pourra pas la modifier.                        |
| &             | Passage par rÃ©fÃ©rence â†’ Ã©vite de faire une copie de l'objet (plus performant).             |
| e             | Nom de la variable qui reprÃ©sente l'exception attrapÃ©e. AccÃ¨s aux infos avec .what().      |
+----------------+-------------------------------------------------------------------------------------------+
 

Exemple

catch (const std::exception &e)
{
    std::cerr << "Erreur : " << e.what() << std::endl;
}

Ici, on attrape toutes les exceptions qui hÃ©ritent de std::exception.
e est une rÃ©fÃ©rence constante vers l'exception, et on peut afficher son message avec e.what().

ðŸ”¥ Exemple avec plusieurs types :
---------------------------------

catch (const std::out_of_range &e) // Attrape uniquement les exceptions out_of_range
{
    std::cerr << "Erreur hors limites : " << e.what() << std::endl;
}
catch (const std::exception &e) // Attrape les autres exceptions standard
{
    std::cerr << "Erreur : " << e.what() << std::endl;
}

**************************************************************************************************************************************
