# Gestion des exceptions en C++ ‚Äî try / catch

## üöÄ Qu‚Äôest-ce qu‚Äôune exception ? :

Une **exception** est un m√©canisme qui permet de **g√©rer les erreurs** ou les situations anormales pendant l‚Äôex√©cution du programme.  

Quand un probl√®me survient, on peut **lancer** (`throw`) une exception.  
Si elle n'est pas **attrap√©e** (`catch`), le programme se **termine brutalement**.

---

## üü¢ Syntaxe g√©n√©rale :
```cpp
try
{
    // Code qui pourrait g√©n√©rer une exception
}
catch (const TypeException &e)
{
    // Code pour g√©rer l'exception
}
```

### Exemple simple :

```cpp
#include <iostream>
#include <exception>

int main()
{
    try
    {
        throw std::runtime_error("Une erreur est survenue !");
    }
    catch (const std::exception &e)
    {
        std::cerr << "Erreur attrap√©e : " << e.what() << std::endl;
    }

    std::cout << "Le programme continue." << std::endl;
    return 0;
}
```

### R√©sultat :

Erreur attrap√©e : Une erreur est survenue !
Le programme continue.

### Pourquoi utiliser try / catch ? :

Emp√™cher que le programme plante brutalement en cas d'erreur

R√©cup√©rer et traiter l'information sur l'erreur

Prot√©ger les zones critiques du programme

### Le m√©canisme complet :

throw ‚Üí Permet de lancer une exception.

try ‚Üí Prot√®ge un bloc de code.

catch ‚Üí Attrape l'exception et agit en cons√©quence.

### Plusieurs catch :

On peut attraper plusieurs types d‚Äôexceptions :
```cpp
try
{
    // Code qui peut g√©n√©rer plusieurs types d'exceptions
}
catch (const std::invalid_argument &e)
{
    std::cerr << "Argument invalide : " << e.what() << std::endl;
}
catch (const std::out_of_range &e)
{
    std::cerr << "Hors limites : " << e.what() << std::endl;
}
catch (const std::exception &e)
{
    std::cerr << "Autre erreur : " << e.what() << std::endl;
}
```

### Attraper toutes les exceptions :

Il existe un catch sp√©cial qui attrape n'importe quelle exception :

```cpp
try
{
    // Code
}
catch (...)
{
    std::cerr << "Une exception inconnue a √©t√© attrap√©e." << std::endl;
}
```

### Cr√©er sa propre exception :

On peut cr√©er une classe d‚Äôexception en h√©ritant de std::exception :

```cpp
#include <exception>

class MyException : public std::exception
{
public:
    const char* what() const noexcept override
    {
        return "Ceci est une exception personnalis√©e.";
    }
};
```

### Utilisation :

```cpp
try
{
    throw MyException();
}
catch (const MyException &e)
{
    std::cerr << e.what() << std::endl;
}
```

### Les arguments de catch :

Quand on √©crit un bloc catch, on doit indiquer le type d‚Äôexception que l‚Äôon veut attraper.

### Structure :

```cpp
catch (const TypeException &e)
```

| √âl√©ment          | Signification                                                                     |
|------------------|-----------------------------------------------------------------------------------|
| **TypeException** | Type de l'exception √† attraper (ex : `std::exception`, `std::runtime_error`).     |
| **const**         | L‚Äôexception est en lecture seule ‚Üí on ne peut pas la modifier.                   |
| **&**             | Passage par r√©f√©rence ‚Üí √©vite la copie de l‚Äôobjet (plus performant).             |
| **e**             | Nom de la variable repr√©sentant l'exception (acc√®s au message via `e.what()`).   |


### Exemple :

```cpp
catch (const std::exception &e)
{
    std::cerr << "Erreur : " << e.what() << std::endl;
}
```

### Exemple avec plusieurs types :

```cpp
catch (const std::out_of_range &e) // Attrape uniquement out_of_range
{
    std::cerr << "Erreur hors limites : " << e.what() << std::endl;
}
catch (const std::exception &e) // Attrape les autres exceptions standard
{
    std::cerr << "Erreur : " << e.what() << std::endl;
}
```
